Workbook

Sheet 시료채취 작성
B2: 시료채취기록부 | O2: 시설약자 | P2: GSP
O3: 사용 샘플러(입자) | P3: 입자샘플러4 | Q3: 사용 샘플러(가스) | R3: 가스샘플러1
B4: 사업장명 | C4: 지에스파워㈜ 부천열병합발전처 | E4: 업종 | F4: 화력발전업(35113) | I4: 배출시설 | J4: 가스터빈 | L4: 굴뚝명 | M4: #A-30
B5: 현장기상 | C5: 채취일 | D5: 기상 | E5: 기온 | G5: 습도 | I5: 기압 | K5: 풍향 | M5: 풍속 | O5: 입자샘플러 | P5: SN. | Q5: Yd | R5: 가스샘플러 | S5: SN. | T5: Yd
C6: 46322 | D6: 맑음 | E6: 24.8 | F6: ℃ | G6: 36 | H6: % | I6: 770 | J6: mmHg | K6: 동 | L6: 풍 | M6: 2.3 | N6: m/s | O6: #1 | P6: 1910162K | Q6: 0.991 | R6: #1 | S6: 1910122 | T6: 0.9857 | U6: 26 상반기
C7: 46323 | D7: 맑음 | E7: 28.9 | F7: ℃ | G7: 25 | H7: % | I7: 778 | J7: mmHg | K7: 동 | L7: 풍 | M7: 2.5 | N7: m/s | O7: #2 | P7: 1910163K | Q7: 0.994 | R7: #2 | S7: 1910123 | T7: 1.0036
F8: ℃ | H8: % | J8: mmHg | L8: 풍 | N8: m/s | O8: #3 | P8: 1910164K | Q8: 1.0078 | R8: #3 | S8: 1910124 | T8: 0.9985
F9: ℃ | H9: % | J9: mmHg | L9: 풍 | N9: m/s | O9: #4 | P9: 1910165K | Q9: 0.9976 | R9: #4 | S9: 1910125 | T9: 0.9892
O10: #5 | P10: A2312850 | Q10: 1 | R10: #5 | S10: A2304264 | T10: 1
B11: 물질명 | C11: 의뢰항목 | D11: 시료번호 (날짜-사업장-굴뚝-항목) | E11: sampler No. | F11: 측정일시 | I11: 채취유량 | L11: 가스 샘플러(가스미터) | O11: 공정시험기준 | S11: 시험검사기간 | T11: 분석기한
F12: 날짜 | G12: 시작 | H12: 종료 | I12: 시작값 | J12: 종료값 | K12: 채취유량(L) | L12: 온도(℃) | M12: 압력(mmH2O) | N12: 압력(mmHg) | O12: 흡입속도(L/min) | P12: 채취유량(L) | Q12: 소요시간(min)
A13: P | B13: 먼지 | C13: O | D13: =IF(C13="","",TEXT($C$6,"mmdd")&"-"&$P$2&"-"&$M$4&"-"&A13&"-1") -> 1027-GSP-#A-30-P-1 | E13: =IF(C13="","",$P$3) -> 입자샘플러4 | F13: =IF(C13="","",$C$6) -> 46322 | G13: 0.59097222 | H13: 0.63263889 | I13: 5572.68 | J13: 6773.53 | K13: =IF($I13="","",(J13-I13)*$Q$9) -> 1197.968 | N13: =IF(M13="","",M13/10332.275*760) | P13: 1000 | S13: 2 | T13: =IF(F13="","",(WORKDAY(F13,DAY(S13),0))) -> 46324
A14: G | B14: 황산화물 | C14: O | D14: =IF(C14="","",TEXT($C$6,"mmdd")&"-"&$P$2&"-"&$M$4&"-"&A14&"-1~3") -> 1027-GSP-#A-30-G-1~3 | E14: =IF(C14="","","가스분석기") -> 가스분석기 | F14: =IF(C14="","",$C$6) -> 46322 | G14: 0.48263889 | H14: 0.49305556 | Q14: 15 | S14: 현장측정 | T14: 현장측정 | V14: =IF(K14="","",K14*(273/(273+$L14))*($I$6+$N14)/760)
A15: G | B15: 질소산화물 | D15: =IF(C15="","",TEXT($C$6,"mmdd")&"-"&$P$2&"-"&$M$4&"-"&A15&"-1~3") | E15: =IF(C15="","","가스분석기") | F15: =IF(C15="","",$C$6) | Q15: 15 | S15: 현장측정 | T15: 현장측정 | V15: =IF(K15="","",K15*(273/(273+$L15))*($I$6+$N15)/760)
A16: G | B16: 일산화탄소 | D16: =IF(C16="","",TEXT($C$6,"mmdd")&"-"&$P$2&"-"&$M$4&"-"&A16&"-1") | E16: =IF(C16="","","가스분석기") | F16: =IF(C16="","",$C$6) | Q16: 15 | S16: 현장측정 | T16: 현장측정 | V16: =IF(K16="","",K16*(273/(273+$L16))*($I$6+$N16)/760)
A17: NH3 | B17: 암모니아-1(BA) | C17: O | D17: =IF(C17="","",TEXT($C$7,"mmdd")&"-"&$P$2&"-"&$M$4&"-"&A17&"-BA-1") -> 1028-GSP-#A-30-NH3-BA-1 | E17: =IF(C17="","",$R$3) -> 가스샘플러1 | F17: =IF(C17="","",$C$7) -> 46323 | G17: 0.47777778 | H17: 0.48680556 | I17: 2109.15 | J17: 2129.5 | K17: =IF(I17="","",(J17-I17)*$T$6) -> 20.058995 | L17: 25 | M17: 20 | N17: =IF(M17="","",M17/13.6) -> 1.4705882 | O17: 1~2 | P17: 20 | Q17: 20 | S17: 3 | T17: =IF(F17="","",(WORKDAY(F17,DAY(S17),0))) -> 46328 | V17: =IF(K17="","",K17*(273/(273+$L17))*($I$6+$N17)/760) -> 18.653543
A18: NH3 | B18: 암모니아-2(H2O2) | D18: =IF($C$17="","",TEXT($C$7,"mmdd")&"-"&$P$2&"-"&$M$4&"-"&A18&"-H2O2-1") -> 1028-GSP-#A-30-NH3-H2O2-1 | E18: =IF(C17="","",$R$3) -> 가스샘플러1 | F18: =IF(C17="","",$C$7) -> 46323 | G18: 0.4875 | H18: 0.49583333 | I18: 2129.5 | J18: 2150.1 | K18: =IF(I18="","",(J18-I18)*$T$6) -> 20.30542 | L18: 25 | M18: 20 | N18: =IF(M18="","",M18/13.6) -> 1.4705882 | O18: 1~2 | P18: 20 | Q18: 20 | S18: 3 | T18: =IF(F18="","",(WORKDAY(F18,DAY(S18),0))) -> 46328 | V18: =IF(K18="","",K18*(273/(273+$L18))*($I$6+$N18)/760) -> 18.882702
A19: F | B19: 불소 | D19: =IF(C19="","",TEXT($C$6,"mmdd")&"-"&$P$2&"-"&$M$4&"-"&A19&"-1") | E19: =IF(C19="","",$R$3) | F19: =IF(C19="","",$C$6) | K19: =IF(I19="","",(J19-I19)*$T$6) | N19: =IF(M19="","",M19/13.6) | O19: 1 | P19: 40 | Q19: 40 | S19: 4 | T19: =IF(F19="","",(WORKDAY(F19,DAY(S19),0))) | V19: =IF(K19="","",K19*(273/(273+$L19))*($I$6+$N19)/760)
A20: HCl | B20: 염화수소 | D20: =IF(C20="","",TEXT($C$6,"mmdd")&"-"&$P$2&"-"&$M$4&"-"&A20&"-1") | E20: =IF(C20="","",$R$3) | F20: =IF(C20="","",$C$6) | K20: =IF(I20="","",(J20-I20)*$T$6) | N20: =IF(M20="","",M20/13.6) | O20: 1 | P20: 20 | Q20: 20 | S20: 3 | T20: =IF(F20="","",(WORKDAY(F20,DAY(S20),0))) | V20: =IF(K20="","",K20*(273/(273+$L20))*($I$6+$N20)/760)
A21: H2S | B21: 황화수소 | C21: O | D21: =IF(C21="","",TEXT($C$6,"mmdd")&"-"&$P$2&"-"&$M$4&"-"&A21&"-1") -> 1027-GSP-#A-30-H2S-1 | E21: =IF(C21="","",$R$3) -> 가스샘플러1 | F21: =IF(C21="","",$C$6) -> 46322 | G21: 0.54930556 | H21: 0.56458333 | I21: 2088.5 | J21: 2109.1 | K21: =IF(I21="","",(J21-I21)*$T$6) -> 20.30542 | L21: 29 | M21: 18 | N21: =IF(M21="","",M21/13.6) -> 1.3235294 | O21: 1 | P21: 20 | Q21: 20 | S21: 4 | T21: =IF(F21="","",(WORKDAY(F21,DAY(S21),0))) -> 46328 | V21: =IF(K21="","",K21*(273/(273+$L21))*($I$6+$N21)/760) -> 18.629048
A22: HCN | B22: 시안화수소 | D22: =IF(C22="","",TEXT($C$6,"mmdd")&"-"&$P$2&"-"&$M$4&"-"&A22&"-1") | E22: =IF(C22="","",$R$3) | F22: =IF(C22="","",$C$6) | K22: =IF(I22="","",(J22-I22)*$T$6) | N22: =IF(M22="","",M22/13.6) | O22: 1 | P22: 10 | Q22: 10 | S22: 3 | T22: =IF(F22="","",(WORKDAY(F22,DAY(S22),0))) | V22: =IF(K22="","",K22*(273/(273+$L22))*($I$6+$N22)/760)
A23: HDZ | B23: 하이드라진 | D23: =IF(C23="","",TEXT($C$6,"mmdd")&"-"&$P$2&"-"&$M$4&"-"&A23&"-1") | E23: =IF(C23="","",$R$3) | F23: =IF(C23="","",$C$6) | K23: =IF(I23="","",(J23-I23)*$T$6) | N23: =IF(M23="","",M23/13.6) | O23: 1 | P23: 10 | Q23: 10 | S23: 3 | T23: =IF(F23="","",(WORKDAY(F23,DAY(S23),0))) | V23: =IF(K23="","",K23*(273/(273+$L23))*($I$6+$N23)/760)
A24: CS2 | B24: 이황화탄소 | D24: =IF(C24="","",TEXT($C$6,"mmdd")&"-"&$P$2&"-"&$M$4&"-"&A24&"-1") | E24: =IF(C24="","",$R$3) | F24: =IF(C24="","",$C$6) | K24: =IF(I24="","",(J24-I24)*$T$6) | S24: 9 | T24: =IF(F24="","",(WORKDAY(F24,DAY(S24),0))) | V24: =IF(K24="","",K24*(273/(273+$L24))*($I$6+$N24)/760)
A25: M | B25: 구리 | D25: =IF(C25="","",TEXT($C$6,"mmdd")&"-"&$P$2&"-"&$M$4&"-"&A25&"-1") | E25: =IF(C25="","",$P$3) | F25: =IF(C25="","",$C$6) | K25: =IF($I25="","",(J25-I25)*$Q$9) | P25: 1000 | S25: 6 | T25: =IF(F25="","",(WORKDAY(F25,DAY(S25),0))) | V25: =IF(K25="","",K25*(273/(273+$L25))*($I$6+$N25)/760)
A26: M | B26: 카드뮴 | C26: O | D26: =IF(C26="","",TEXT($C$7,"mmdd")&"-"&$P$2&"-"&$M$4&"-"&A26&"-1") -> 1028-GSP-#A-30-M-1 | E26: =IF(C26="","",$P$3) -> 입자샘플러4 | F26: =IF(C26="","",$C$7) -> 46323 | G26: 0.47777778 | H26: 0.53333333 | I26: 6783.07 | J26: 7951.86 | K26: =IF($I26="","",(J26-I26)*$Q$9) -> 1165.9849 | S26: 6 | T26: =IF(F26="","",(WORKDAY(F26,DAY(S26),0))) -> 46331 | V26: =IF(K26="","",K26*(273/(273+$L26))*($I$6+$N26)/760) -> 1181.3268
A27: M | B27: 납 | C27: O | D27: =IF(C27="","",TEXT($C$7,"mmdd")&"-"&$P$2&"-"&$M$4&"-"&A27&"-1") -> 1028-GSP-#A-30-M-1 | E27: =IF(C27="","",$P$3) -> 입자샘플러4 | F27: =IF(C27="","",$C$7) -> 46323 | G27: 0.47777778 | H27: 0.53333333 | I27: 6783.07 | J27: 7951.86 | K27: =IF($I27="","",(J27-I27)*$Q$9) -> 1165.9849 | S27: 6 | T27: =IF(F27="","",(WORKDAY(F27,DAY(S27),0))) -> 46331 | V27: =IF(K27="","",K27*(273/(273+$L27))*($I$6+$N27)/760) -> 1181.3268
A28: M | B28: 크롬 | C28: O | D28: =IF(C28="","",TEXT($C$7,"mmdd")&"-"&$P$2&"-"&$M$4&"-"&A28&"-1") -> 1028-GSP-#A-30-M-1 | E28: =IF(C28="","",$P$3) -> 입자샘플러4 | F28: =IF(C28="","",$C$7) -> 46323 | G28: 0.47777778 | H28: 0.53333333 | I28: 6783.07 | J28: 7951.86 | K28: =IF($I28="","",(J28-I28)*$Q$9) -> 1165.9849 | S28: 6 | T28: =IF(F28="","",(WORKDAY(F28,DAY(S28),0))) -> 46331 | V28: =IF(K28="","",K28*(273/(273+$L28))*($I$6+$N28)/760) -> 1181.3268
A29: M | B29: 니켈 | C29: O | D29: =IF(C29="","",TEXT($C$7,"mmdd")&"-"&$P$2&"-"&$M$4&"-"&A29&"-1") -> 1028-GSP-#A-30-M-1 | E29: =IF(C29="","",$P$3) -> 입자샘플러4 | F29: =IF(C29="","",$C$7) -> 46323 | G29: 0.47777778 | H29: 0.53333333 | I29: 6783.07 | J29: 7951.86 | K29: =IF($I29="","",(J29-I29)*$Q$9) -> 1165.9849 | S29: 6 | T29: =IF(F29="","",(WORKDAY(F29,DAY(S29),0))) -> 46331 | V29: =IF(K29="","",K29*(273/(273+$L29))*($I$6+$N29)/760) -> 1181.3268
A30: M | B30: 아연 | D30: =IF(C30="","",TEXT($C$6,"mmdd")&"-"&$P$2&"-"&$M$4&"-"&A30&"-1") | E30: =IF(C30="","",$P$3) | F30: =IF(C30="","",$C$6) | K30: =IF($I30="","",(J30-I30)*$Q$9) | S30: 6 | T30: =IF(F30="","",(WORKDAY(F30,DAY(S30),0))) | V30: =IF(K30="","",K30*(273/(273+$L30))*($I$6+$N30)/760)
A31: M | B31: 베릴륨 | D31: =IF(C31="","",TEXT($C$6,"mmdd")&"-"&$P$2&"-"&$M$4&"-"&A31&"-1") | E31: =IF(C31="","",$P$3) | F31: =IF(C31="","",$C$6) | K31: =IF($I31="","",(J31-I31)*$Q$9) | S31: 6 | T31: =IF(F31="","",(WORKDAY(F31,DAY(S31),0))) | V31: =IF(K31="","",K31*(273/(273+$L31))*($I$6+$N31)/760)
A32: M | B32: 비소(입자상) | C32: O | D32: =IF(C32="","",TEXT($C$7,"mmdd")&"-"&$P$2&"-"&$M$4&"-"&A32&"-1") -> 1028-GSP-#A-30-M-1 | E32: =IF(C32="","",$P$3) -> 입자샘플러4 | F32: =IF(C32="","",$C$7) -> 46323 | G32: 0.47777778 | H32: 0.53333333 | I32: 6783.07 | J32: 7951.86 | K32: =IF($I32="","",(J32-I32)*$Q$9) -> 1165.9849 | P32: 1000 | S32: 9 | T32: =IF(F32="","",(WORKDAY(F32,DAY(S32),0))) -> 46336 | V32: =IF(K32="","",K32*(273/(273+$L32))*($I$6+$N32)/760) -> 1181.3268
A33: As-G | B33: 비소(가스상) | D33: =IF($C$32="","",TEXT($C$7,"mmdd")&"-"&$P$2&"-"&$M$4&"-"&A33&"-1") -> 1028-GSP-#A-30-As-G-1 | E33: =IF(C32="","",$P$3) -> 입자샘플러4 | F33: =IF(C32="","",$C$7) -> 46323 | G33: 0.47777778 | H33: 0.53333333 | I33: 6783.07 | J33: 7951.86 | K33: =IF($I33="","",(J33-I33)*$Q$9) -> 1165.9849 | O33: 1 | Q33: 입자상 동일 | V33: =IF(K33="","",K33*(273/(273+$L33))*($I$6+$N33)/760) -> 1181.3268
A34: Hg | B34: 수은 | C34: O | D34: =IF(C34="","",TEXT($C$6,"mmdd")&"-"&$P$2&"-"&$M$4&"-"&A34&"-1") -> 1027-GSP-#A-30-Hg-1 | E34: =IF(C34="","",$P$3) -> 입자샘플러4 | F34: =IF(C34="","",$C$6) -> 46322 | G34: 0.52083333 | H34: 0.5625 | I34: 4306.48 | J34: 5563.61 | K34: =IF($I34="","",(J34-I34)*$Q$9) -> 1254.1129 | P34: 1000 | S34: 9 | T34: =IF(F34="","",(WORKDAY(F34,DAY(S34),0))) -> 46335 | V34: =IF(K34="","",K34*(273/(273+$L34))*($I$6+$N34)/760) -> 1270.6144 | XEG34: 수
A35: ALD-1 | B35: 알데히드-1 | C35: O | D35: =IF(C35="","",TEXT($C$6,"mmdd")&"-"&$P$2&"-"&$M$4&"-"&A35) -> 1027-GSP-#A-30-ALD-1 | E35: =IF(C35="","",$R$3) -> 가스샘플러1 | F35: =IF(C35="","",$C$6) -> 46322 | G35: 0.52083333 | H35: 0.52777778 | I35: 2055.35 | J35: 2065.6 | K35: =IF($I35="","",(J35-I35)*$T$6) -> 10.103425 | L35: 25 | M35: 15 | N35: =IF(M35="","",M35/13.6) -> 1.1029412 | O35: 1 | P35: 10 | S35: 7 | T35: =IF(F35="","",(WORKDAY(F35,DAY(S35),0))) -> 46331 | V35: =IF(K35="","",K35*(273/(273+$L35))*($I$6+$N35)/760) -> 9.3910418
A36: ALD-2 | B36: 알데히드-2 | D36: =IF(C35="","",TEXT($C$6,"mmdd")&"-"&$P$2&"-"&$M$4&"-"&A36) -> 1027-GSP-#A-30-ALD-2 | E36: =IF(C35="","",$R$3) -> 가스샘플러1 | F36: =IF(C35="","",$C$6) -> 46322 | G36: 0.52847222 | H36: 0.5375 | I36: 2065 | J36: 2078.3 | K36: =IF($I36="","",(J36-I36)*$T$6) -> 13.10981 | L36: 26 | M36: 18 | N36: =IF(M36="","",M36/13.6) -> 1.3235294 | O36: 1 | P36: 10 | V36: =IF(K36="","",K36*(273/(273+$L36))*($I$6+$N36)/760) -> 12.14817
A37: ALD-3 | B37: 알데히드-3 | D37: =IF(C35="","",TEXT($C$6,"mmdd")&"-"&$P$2&"-"&$M$4&"-"&A37) -> 1027-GSP-#A-30-ALD-3 | E37: =IF(C35="","",$R$3) -> 가스샘플러1 | F37: =IF(C35="","",$C$6) -> 46322 | G37: 0.53888889 | H37: 0.54652778 | I37: 2078.3 | J37: 2088.5 | K37: =IF($I37="","",(J37-I37)*$T$6) -> 10.05414 | L37: 27 | M37: 18 | N37: =IF(M37="","",M37/13.6) -> 1.3235294 | O37: 1 | P37: 10 | V37: =IF(K37="","",K37*(273/(273+$L37))*($I$6+$N37)/760) -> 9.2855858
A38: PN | B38: 페놀 | D38: =IF(C38="","",TEXT($C$6,"mmdd")&"-"&$P$2&"-"&$M$4&"-"&A38&"-1") | E38: =IF(C38="","",$R$3) | F38: =IF(C38="","",$C$6) | K38: =IF($I38="","",(J38-I38)*$T$6) | N38: =IF(M38="","",M38/13.6) | O38: 1 | P38: 20 | S38: 4 | T38: =IF(F38="","",(WORKDAY(F38,DAY(S38),0))) | V38: =IF(K38="","",K38*(273/(273+$L38))*($I$6+$N38)/760)
A39: Br | B39: 브롬 | D39: =IF(C39="","",TEXT($C$6,"mmdd")&"-"&$P$2&"-"&$M$4&"-"&A39&"-1") | E39: =IF(C39="","",$R$3) | F39: =IF(C39="","",$C$6) | K39: =IF($I39="","",(J39-I39)*$T$6) | N39: =IF(M39="","",M39/13.6) | O39: 1 | P39: 40 | S39: 4 | T39: =IF(F39="","",(WORKDAY(F39,DAY(S39),0))) | V39: =IF(K39="","",K39*(273/(273+$L39))*($I$6+$N39)/760)
A40: THC | B40: 총탄화수소 | E40: =IF(C40="","","총탄화수소측정기") | F40: =IF(C40="","",$C$6) | Q40: 30 | S40: 현장측정 | V40: =IF(K40="","",K40*(273/(273+$L40))*($I$6+$N40)/760)
A41: BZ | B41: 벤조(a)피렌 | D41: =IF(C41="","",TEXT($C$6,"mmdd")&"-"&$P$2&"-"&$M$4&"-"&A41&"-1") | F41: =IF(C41="","",$C$6) | K41: =IF(I41="","",J41-I41) | S41: 9 | T41: =IF(F41="","",(WORKDAY(F41,DAY(S41),0))) | V41: =IF(K41="","",K41*(273/(273+$L41))*($I$6+$N41)/760)
...

Sheet 20261027
A2: 시료채취기록부 | J2: 기술책임자
A7: 사업장명 | B7: ='시료채취 작성'!C4 -> 지에스파워㈜ 부천열병합발전처 | C7: 업종 | D7: ='시료채취 작성'!F4 -> 화력발전업(35113) | G7: 굴뚝명 | H7: ='시료채취 작성'!M4 -> #A-30 | I7: 날짜 | J7: ='시료채취 작성'!C6 -> 46322
A8: 기상 | B8: 기온(℃) | C8: 습도(%) | E8: 기압(mmHg) | G8: 풍향 | I8: 풍속(m/s)
A9: =IF(J7='시료채취 작성'!C6,'시료채취 작성'!D6," ") -> 맑음 | B9: =IF(J7='시료채취 작성'!C6,'시료채취 작성'!E6," ") -> 24.8 | C9: =IF(J7='시료채취 작성'!C6,'시료채취 작성'!G6) -> 36 | E9: =IF(J7='시료채취 작성'!C6,'시료채취 작성'!I6," ") -> 770 | G9: =IF(J7='시료채취 작성'!C6,'시료채취 작성'!K6," ") -> 동 | I9: =IF(J7='시료채취 작성'!C6,'시료채취 작성'!M6," ") -> 2.3
A10: 물질명 | B10: 시료번호 | C10: sampler No. | D10: 측정일시 | F10: 채취유량 | I10: 샘플러 | M10: 시험검사기간 | N10: 분석기한
D11: 시작 | E11: 종료 | F11: 시작값 | G11: 종료값 | H11: 채취유량(L) | I11: 온도(℃) | J11: 압력(mmH2O) | K11: 압력(mmHg)
A12: 먼지 | B12: =IF($J$7='시료채취 작성'!F13,'시료채취 작성'!D13,"") -> 1027-GSP-#A-30-P-1 | C12: =IF($J$7='시료채취 작성'!$F13,'시료채취 작성'!E13,"") -> 입자샘플러4 | D12: =IF($J$7='시료채취 작성'!$F13,'시료채취 작성'!G13,"") -> 0.59097222 | E12: =IF($J$7='시료채취 작성'!$F13,'시료채취 작성'!H13,"") -> 0.63263889 | F12: =IF($J$7='시료채취 작성'!$F13,'시료채취 작성'!I13,"") -> 5572.68 | G12: =IF($J$7='시료채취 작성'!$F13,'시료채취 작성'!J13,"") -> 6773.53 | H12: =IF($J$7='시료채취 작성'!$F13,'시료채취 작성'!K13,"") -> 1197.968 | M12: 2 | N12: =IF(B12="","",(WORKDAY($J$7,DAY(M12),0))) -> 46324
A13: 황산화물 | B13: =IF($J$7='시료채취 작성'!F14,'시료채취 작성'!D14,"") -> 1027-GSP-#A-30-G-1~3 | C13: =IF($J$7='시료채취 작성'!$F14,'시료채취 작성'!E14,"") -> 가스분석기 | D13: =IF($J$7='시료채취 작성'!$F14,'시료채취 작성'!G14,"") -> 0.48263889 | E13: =IF($J$7='시료채취 작성'!$F14,'시료채취 작성'!H14,"") -> 0.49305556 | M13: 현장측정 | N13: 현장측정
A14: 질소산화물 | B14: =IF($J$7='시료채취 작성'!F15,'시료채취 작성'!D15,"") | C14: =IF($J$7='시료채취 작성'!$F15,'시료채취 작성'!E15,"") | D14: =IF($J$7='시료채취 작성'!$F15,'시료채취 작성'!G15,"") | E14: =IF($J$7='시료채취 작성'!$F15,'시료채취 작성'!H15,"") | M14: 현장측정 | N14: 현장측정
A15: 일산화탄소 | B15: =IF($J$7='시료채취 작성'!F16,'시료채취 작성'!D16,"") | C15: =IF($J$7='시료채취 작성'!$F16,'시료채취 작성'!E16,"") | D15: =IF($J$7='시료채취 작성'!$F16,'시료채취 작성'!G16,"") | E15: =IF($J$7='시료채취 작성'!$F16,'시료채취 작성'!H16,"") | M15: 현장측정 | N15: 현장측정
A16: 암모니아(BA) | B16: =IF($J$7='시료채취 작성'!F17,'시료채취 작성'!D17,"") | C16: =IF($J$7='시료채취 작성'!$F17,'시료채취 작성'!E17,"") | D16: =IF($J$7='시료채취 작성'!$F17,'시료채취 작성'!G17,"") | E16: =IF($J$7='시료채취 작성'!$F17,'시료채취 작성'!H17,"") | F16: =IF($J$7='시료채취 작성'!$F17,'시료채취 작성'!I17,"") | G16: =IF($J$7='시료채취 작성'!$F17,'시료채취 작성'!J17,"") | H16: =IF($J$7='시료채취 작성'!$F17,'시료채취 작성'!K17,"") | I16: =IF($J$7='시료채취 작성'!$F17,'시료채취 작성'!L17,"") | J16: =IF($J$7='시료채취 작성'!$F17,'시료채취 작성'!M17,"") | K16: =IF($J$7='시료채취 작성'!$F17,'시료채취 작성'!N17,"") | M16: 3 | N16: =IF(B16="","",(WORKDAY($J$7,DAY(M17),0)))
A17: 암모니아(HP) | B17: =IF($J$7='시료채취 작성'!F18,'시료채취 작성'!D18,"") | C17: =IF($J$7='시료채취 작성'!$F18,'시료채취 작성'!E18,"") | D17: =IF($J$7='시료채취 작성'!$F18,'시료채취 작성'!G18,"") | E17: =IF($J$7='시료채취 작성'!$F18,'시료채취 작성'!H18,"") | F17: =IF($J$7='시료채취 작성'!$F18,'시료채취 작성'!I18,"") | G17: =IF($J$7='시료채취 작성'!$F18,'시료채취 작성'!J18,"") | H17: =IF($J$7='시료채취 작성'!$F18,'시료채취 작성'!K18,"") | I17: =IF($J$7='시료채취 작성'!$F18,'시료채취 작성'!L18,"") | J17: =IF($J$7='시료채취 작성'!$F18,'시료채취 작성'!M18,"") | K17: =IF($J$7='시료채취 작성'!$F18,'시료채취 작성'!N18,"") | M17: 3 | N17: =IF(B17="","",(WORKDAY($J$7,DAY(M17),0)))
A18: 불소 | B18: =IF($J$7='시료채취 작성'!F19,'시료채취 작성'!D19,"") | C18: =IF($J$7='시료채취 작성'!$F19,'시료채취 작성'!E19,"") | D18: =IF($J$7='시료채취 작성'!$F19,'시료채취 작성'!G19,"") | E18: =IF($J$7='시료채취 작성'!$F19,'시료채취 작성'!H19,"") | F18: =IF($J$7='시료채취 작성'!$F19,'시료채취 작성'!I19,"") | G18: =IF($J$7='시료채취 작성'!$F19,'시료채취 작성'!J19,"") | H18: =IF($J$7='시료채취 작성'!$F19,'시료채취 작성'!K19,"") | I18: =IF($J$7='시료채취 작성'!$F19,'시료채취 작성'!L19,"") | J18: =IF($J$7='시료채취 작성'!$F19,'시료채취 작성'!M19,"") | K18: =IF($J$7='시료채취 작성'!$F19,'시료채취 작성'!N19,"") | M18: 4 | N18: =IF(B18="","",(WORKDAY($J$7,DAY(M18),0)))
A19: 염화수소 | B19: =IF($J$7='시료채취 작성'!F20,'시료채취 작성'!D20,"") | C19: =IF($J$7='시료채취 작성'!$F20,'시료채취 작성'!E20,"") | D19: =IF($J$7='시료채취 작성'!$F20,'시료채취 작성'!G20,"") | E19: =IF($J$7='시료채취 작성'!$F20,'시료채취 작성'!H20,"") | F19: =IF($J$7='시료채취 작성'!$F20,'시료채취 작성'!I20,"") | G19: =IF($J$7='시료채취 작성'!$F20,'시료채취 작성'!J20,"") | H19: =IF($J$7='시료채취 작성'!$F20,'시료채취 작성'!K20,"") | I19: =IF($J$7='시료채취 작성'!$F20,'시료채취 작성'!L20,"") | J19: =IF($J$7='시료채취 작성'!$F20,'시료채취 작성'!M20,"") | K19: =IF($J$7='시료채취 작성'!$F20,'시료채취 작성'!N20,"") | M19: 3 | N19: =IF(B19="","",(WORKDAY($J$7,DAY(M19),0)))
A20: 황화수소 | B20: =IF($J$7='시료채취 작성'!F21,'시료채취 작성'!D21,"") -> 1027-GSP-#A-30-H2S-1 | C20: =IF($J$7='시료채취 작성'!$F21,'시료채취 작성'!E21,"") -> 가스샘플러1 | D20: =IF($J$7='시료채취 작성'!$F21,'시료채취 작성'!G21,"") -> 0.54930556 | E20: =IF($J$7='시료채취 작성'!$F21,'시료채취 작성'!H21,"") -> 0.56458333 | F20: =IF($J$7='시료채취 작성'!$F21,'시료채취 작성'!I21,"") -> 2088.5 | G20: =IF($J$7='시료채취 작성'!$F21,'시료채취 작성'!J21,"") -> 2109.1 | H20: =IF($J$7='시료채취 작성'!$F21,'시료채취 작성'!K21,"") -> 20.30542 | I20: =IF($J$7='시료채취 작성'!$F21,'시료채취 작성'!L21,"") -> 29 | J20: =IF($J$7='시료채취 작성'!$F21,'시료채취 작성'!M21,"") -> 18 | K20: =IF($J$7='시료채취 작성'!$F21,'시료채취 작성'!N21,"") -> 1.3235294 | M20: 4 | N20: =IF(B20="","",(WORKDAY($J$7,DAY(M20),0))) -> 46328
A21: 시안화수소 | B21: =IF($J$7='시료채취 작성'!F22,'시료채취 작성'!D22,"") | C21: =IF($J$7='시료채취 작성'!$F22,'시료채취 작성'!E22,"") | D21: =IF($J$7='시료채취 작성'!$F22,'시료채취 작성'!G22,"") | E21: =IF($J$7='시료채취 작성'!$F22,'시료채취 작성'!H22,"") | F21: =IF($J$7='시료채취 작성'!$F22,'시료채취 작성'!I22,"") | G21: =IF($J$7='시료채취 작성'!$F22,'시료채취 작성'!J22,"") | H21: =IF($J$7='시료채취 작성'!$F22,'시료채취 작성'!K22,"") | I21: =IF($J$7='시료채취 작성'!$F22,'시료채취 작성'!L22,"") | J21: =IF($J$7='시료채취 작성'!$F22,'시료채취 작성'!M22,"") | K21: =IF($J$7='시료채취 작성'!$F22,'시료채취 작성'!N22,"") | M21: 3 | N21: =IF(B21="","",(WORKDAY($J$7,DAY(M21),0)))
A22: 하이드라진 | B22: =IF($J$7='시료채취 작성'!F23,'시료채취 작성'!D23,"") | C22: =IF($J$7='시료채취 작성'!$F23,'시료채취 작성'!E23,"") | D22: =IF($J$7='시료채취 작성'!$F23,'시료채취 작성'!G23,"") | E22: =IF($J$7='시료채취 작성'!$F23,'시료채취 작성'!H23,"") | F22: =IF($J$7='시료채취 작성'!$F23,'시료채취 작성'!I23,"") | G22: =IF($J$7='시료채취 작성'!$F23,'시료채취 작성'!J23,"") | H22: =IF($J$7='시료채취 작성'!$F23,'시료채취 작성'!K23,"") | I22: =IF($J$7='시료채취 작성'!$F23,'시료채취 작성'!L23,"") | J22: =IF($J$7='시료채취 작성'!$F23,'시료채취 작성'!M23,"") | K22: =IF($J$7='시료채취 작성'!$F23,'시료채취 작성'!N23,"")
A23: 이황화탄소 | B23: =IF($J$7='시료채취 작성'!F24,'시료채취 작성'!D24,"") | C23: =IF($J$7='시료채취 작성'!$F24,'시료채취 작성'!E24,"") | D23: =IF($J$7='시료채취 작성'!$F24,'시료채취 작성'!G24,"") | E23: =IF($J$7='시료채취 작성'!$F24,'시료채취 작성'!H24,"") | F23: =IF($J$7='시료채취 작성'!$F24,'시료채취 작성'!I24,"") | G23: =IF($J$7='시료채취 작성'!$F24,'시료채취 작성'!J24,"") | H23: =IF($J$7='시료채취 작성'!$F24,'시료채취 작성'!K24,"") | M23: 9 | N23: =IF(B23="","",(WORKDAY($J$7,DAY(M23),0)))
A24: 구리 | B24: =IF($J$7='시료채취 작성'!F25,'시료채취 작성'!D25,"") | C24: =IF($J$7='시료채취 작성'!$F25,'시료채취 작성'!E25,"") | D24: =IF($J$7='시료채취 작성'!$F25,'시료채취 작성'!G25,"") | E24: =IF($J$7='시료채취 작성'!$F25,'시료채취 작성'!H25,"") | F24: =IF($J$7='시료채취 작성'!$F25,'시료채취 작성'!I25,"") | G24: =IF($J$7='시료채취 작성'!$F25,'시료채취 작성'!J25,"") | H24: =IF($J$7='시료채취 작성'!$F25,'시료채취 작성'!K25,"") | M24: 6 | N24: =IF(B24="","",(WORKDAY($J$7,DAY(M24),0)))
A25: 카드륨 | B25: =IF($J$7='시료채취 작성'!F26,'시료채취 작성'!D26,"") | C25: =IF($J$7='시료채취 작성'!$F26,'시료채취 작성'!E26,"") | D25: =IF($J$7='시료채취 작성'!$F26,'시료채취 작성'!G26,"") | E25: =IF($J$7='시료채취 작성'!$F26,'시료채취 작성'!H26,"") | F25: =IF($J$7='시료채취 작성'!$F26,'시료채취 작성'!I26,"") | G25: =IF($J$7='시료채취 작성'!$F26,'시료채취 작성'!J26,"") | H25: =IF($J$7='시료채취 작성'!$F26,'시료채취 작성'!K26,"") | M25: 6 | N25: =IF(B25="","",(WORKDAY($J$7,DAY(M25),0)))
A26: 납 | B26: =IF($J$7='시료채취 작성'!F27,'시료채취 작성'!D27,"") | C26: =IF($J$7='시료채취 작성'!$F27,'시료채취 작성'!E27,"") | D26: =IF($J$7='시료채취 작성'!$F27,'시료채취 작성'!G27,"") | E26: =IF($J$7='시료채취 작성'!$F27,'시료채취 작성'!H27,"") | F26: =IF($J$7='시료채취 작성'!$F27,'시료채취 작성'!I27,"") | G26: =IF($J$7='시료채취 작성'!$F27,'시료채취 작성'!J27,"") | H26: =IF($J$7='시료채취 작성'!$F27,'시료채취 작성'!K27,"") | M26: 6 | N26: =IF(B26="","",(WORKDAY($J$7,DAY(M26),0)))
A27: 크롬 | B27: =IF($J$7='시료채취 작성'!F28,'시료채취 작성'!D28,"") | C27: =IF($J$7='시료채취 작성'!$F28,'시료채취 작성'!E28,"") | D27: =IF($J$7='시료채취 작성'!$F28,'시료채취 작성'!G28,"") | E27: =IF($J$7='시료채취 작성'!$F28,'시료채취 작성'!H28,"") | F27: =IF($J$7='시료채취 작성'!$F28,'시료채취 작성'!I28,"") | G27: =IF($J$7='시료채취 작성'!$F28,'시료채취 작성'!J28,"") | H27: =IF($J$7='시료채취 작성'!$F28,'시료채취 작성'!K28,"") | M27: 6 | N27: =IF(B27="","",(WORKDAY($J$7,DAY(M27),0)))
A28: 니켈 | B28: =IF($J$7='시료채취 작성'!F29,'시료채취 작성'!D29,"") | C28: =IF($J$7='시료채취 작성'!$F29,'시료채취 작성'!E29,"") | D28: =IF($J$7='시료채취 작성'!$F29,'시료채취 작성'!G29,"") | E28: =IF($J$7='시료채취 작성'!$F29,'시료채취 작성'!H29,"") | F28: =IF($J$7='시료채취 작성'!$F29,'시료채취 작성'!I29,"") | G28: =IF($J$7='시료채취 작성'!$F29,'시료채취 작성'!J29,"") | H28: =IF($J$7='시료채취 작성'!$F29,'시료채취 작성'!K29,"") | M28: 6 | N28: =IF(B28="","",(WORKDAY($J$7,DAY(M28),0)))
A29: 아연 | B29: =IF($J$7='시료채취 작성'!F30,'시료채취 작성'!D30,"") | C29: =IF($J$7='시료채취 작성'!$F30,'시료채취 작성'!E30,"") | D29: =IF($J$7='시료채취 작성'!$F30,'시료채취 작성'!G30,"") | E29: =IF($J$7='시료채취 작성'!$F30,'시료채취 작성'!H30,"") | F29: =IF($J$7='시료채취 작성'!$F30,'시료채취 작성'!I30,"") | G29: =IF($J$7='시료채취 작성'!$F30,'시료채취 작성'!J30,"") | H29: =IF($J$7='시료채취 작성'!$F30,'시료채취 작성'!K30,"") | M29: 6 | N29: =IF(B29="","",(WORKDAY($J$7,DAY(M29),0)))
A30: 베릴륨 | B30: =IF($J$7='시료채취 작성'!F31,'시료채취 작성'!D31,"") | C30: =IF($J$7='시료채취 작성'!$F31,'시료채취 작성'!E31,"") | D30: =IF($J$7='시료채취 작성'!$F31,'시료채취 작성'!G31,"") | E30: =IF($J$7='시료채취 작성'!$F31,'시료채취 작성'!H31,"") | F30: =IF($J$7='시료채취 작성'!$F31,'시료채취 작성'!I31,"") | G30: =IF($J$7='시료채취 작성'!$F31,'시료채취 작성'!J31,"") | H30: =IF($J$7='시료채취 작성'!$F31,'시료채취 작성'!K31,"")
A31: 비소(입자상) | B31: =IF($J$7='시료채취 작성'!F32,'시료채취 작성'!D32,"") | C31: =IF($J$7='시료채취 작성'!$F32,'시료채취 작성'!E32,"") | D31: =IF($J$7='시료채취 작성'!$F32,'시료채취 작성'!G32,"") | E31: =IF($J$7='시료채취 작성'!$F32,'시료채취 작성'!H32,"") | F31: =IF($J$7='시료채취 작성'!$F32,'시료채취 작성'!I32,"") | G31: =IF($J$7='시료채취 작성'!$F32,'시료채취 작성'!J32,"") | H31: =IF($J$7='시료채취 작성'!$F32,'시료채취 작성'!K32,"") | M31: 9 | N31: =IF(B31="","",(WORKDAY($J$7,DAY(M31),0)))
A32: 비소(가스상) | B32: =IF($J$7='시료채취 작성'!F33,'시료채취 작성'!D33,"") | C32: =IF($J$7='시료채취 작성'!$F33,'시료채취 작성'!E33,"") | D32: =IF($J$7='시료채취 작성'!$F33,'시료채취 작성'!G33,"") | E32: =IF($J$7='시료채취 작성'!$F33,'시료채취 작성'!H33,"") | F32: =IF($J$7='시료채취 작성'!$F33,'시료채취 작성'!I33,"") | G32: =IF($J$7='시료채취 작성'!$F33,'시료채취 작성'!J33,"") | H32: =IF($J$7='시료채취 작성'!$F33,'시료채취 작성'!K33,"") | M32: 9 | N32: =IF(B32="","",(WORKDAY($J$7,DAY(M32),0)))
A33: 수은(입자상) 수은(가스상) | B33: =IF($J$7='시료채취 작성'!F34,'시료채취 작성'!D34,"") -> 1027-GSP-#A-30-Hg-1 | C33: =IF($J$7='시료채취 작성'!$F34,'시료채취 작성'!E34,"") -> 입자샘플러4 | D33: =IF($J$7='시료채취 작성'!$F34,'시료채취 작성'!G34,"") -> 0.52083333 | E33: =IF($J$7='시료채취 작성'!$F34,'시료채취 작성'!H34,"") -> 0.5625 | F33: =IF($J$7='시료채취 작성'!$F34,'시료채취 작성'!I34,"") -> 4306.48 | G33: =IF($J$7='시료채취 작성'!$F34,'시료채취 작성'!J34,"") -> 5563.61 | H33: =IF($J$7='시료채취 작성'!$F34,'시료채취 작성'!K34,"") -> 1254.1129 | M33: 9 | N33: =IF(B33="","",(WORKDAY($J$7,DAY(M33),0))) -> 46335
A34: 알데하이드-1 | B34: =IF($J$7='시료채취 작성'!F35,'시료채취 작성'!D35,"") -> 1027-GSP-#A-30-ALD-1 | C34: =IF($J$7='시료채취 작성'!$F35,'시료채취 작성'!E35,"") -> 가스샘플러1 | D34: =IF($J$7='시료채취 작성'!$F35,'시료채취 작성'!G35,"") -> 0.52083333 | E34: =IF($J$7='시료채취 작성'!$F35,'시료채취 작성'!H35,"") -> 0.52777778 | F34: =IF($J$7='시료채취 작성'!$F35,'시료채취 작성'!I35,"") -> 2055.35 | G34: =IF($J$7='시료채취 작성'!$F35,'시료채취 작성'!J35,"") -> 2065.6 | H34: =IF($J$7='시료채취 작성'!$F35,'시료채취 작성'!K35,"") -> 10.103425 | I34: =IF($J$7='시료채취 작성'!$F35,'시료채취 작성'!L35,"") -> 25 | J34: =IF($J$7='시료채취 작성'!$F35,'시료채취 작성'!M35,"") -> 15 | K34: =IF($J$7='시료채취 작성'!$F35,'시료채취 작성'!N35,"") -> 1.1029412 | M34: 7 | N34: =IF(B34="","",(WORKDAY($J$7,DAY(M34),0))) -> 46331
A35: 알데하이드-2 | B35: =IF($J$7='시료채취 작성'!F36,'시료채취 작성'!D36,"") -> 1027-GSP-#A-30-ALD-2 | C35: =IF($J$7='시료채취 작성'!$F36,'시료채취 작성'!E36,"") -> 가스샘플러1 | D35: =IF($J$7='시료채취 작성'!$F36,'시료채취 작성'!G36,"") -> 0.52847222 | E35: =IF($J$7='시료채취 작성'!$F36,'시료채취 작성'!H36,"") -> 0.5375 | F35: =IF($J$7='시료채취 작성'!$F36,'시료채취 작성'!I36,"") -> 2065 | G35: =IF($J$7='시료채취 작성'!$F36,'시료채취 작성'!J36,"") -> 2078.3 | H35: =IF($J$7='시료채취 작성'!$F36,'시료채취 작성'!K36,"") -> 13.10981 | I35: =IF($J$7='시료채취 작성'!$F36,'시료채취 작성'!L36,"") -> 26 | J35: =IF($J$7='시료채취 작성'!$F36,'시료채취 작성'!M36,"") -> 18 | K35: =IF($J$7='시료채취 작성'!$F36,'시료채취 작성'!N36,"") -> 1.3235294 | N35: =IF(B35="","",(WORKDAY($J$7,DAY(M35),0))) -> 46322
A36: 알데하이드-3 | B36: =IF($J$7='시료채취 작성'!F37,'시료채취 작성'!D37,"") -> 1027-GSP-#A-30-ALD-3 | C36: =IF($J$7='시료채취 작성'!$F37,'시료채취 작성'!E37,"") -> 가스샘플러1 | D36: =IF($J$7='시료채취 작성'!$F37,'시료채취 작성'!G37,"") -> 0.53888889 | E36: =IF($J$7='시료채취 작성'!$F37,'시료채취 작성'!H37,"") -> 0.54652778 | F36: =IF($J$7='시료채취 작성'!$F37,'시료채취 작성'!I37,"") -> 2078.3 | G36: =IF($J$7='시료채취 작성'!$F37,'시료채취 작성'!J37,"") -> 2088.5 | H36: =IF($J$7='시료채취 작성'!$F37,'시료채취 작성'!K37,"") -> 10.05414 | I36: =IF($J$7='시료채취 작성'!$F37,'시료채취 작성'!L37,"") -> 27 | J36: =IF($J$7='시료채취 작성'!$F37,'시료채취 작성'!M37,"") -> 18 | K36: =IF($J$7='시료채취 작성'!$F37,'시료채취 작성'!N37,"") -> 1.3235294 | N36: =IF(B36="","",(WORKDAY($J$7,DAY(M36),0))) -> 46322
A37: 페놀 | B37: =IF($J$7='시료채취 작성'!F38,'시료채취 작성'!D38,"") | C37: =IF($J$7='시료채취 작성'!$F38,'시료채취 작성'!E38,"") | D37: =IF($J$7='시료채취 작성'!$F38,'시료채취 작성'!G38,"") | E37: =IF($J$7='시료채취 작성'!$F38,'시료채취 작성'!H38,"") | F37: =IF($J$7='시료채취 작성'!$F38,'시료채취 작성'!I38,"") | G37: =IF($J$7='시료채취 작성'!$F38,'시료채취 작성'!J38,"") | H37: =IF($J$7='시료채취 작성'!$F38,'시료채취 작성'!K38,"") | I37: =IF($J$7='시료채취 작성'!$F38,'시료채취 작성'!L38,"") | J37: =IF($J$7='시료채취 작성'!$F38,'시료채취 작성'!M38,"") | K37: =IF($J$7='시료채취 작성'!$F38,'시료채취 작성'!N38,"") | M37: 4 | N37: =IF(B37="","",(WORKDAY($J$7,DAY(M37),0)))
A38: 브롬 | B38: =IF($J$7='시료채취 작성'!F39,'시료채취 작성'!D39,"") | C38: =IF($J$7='시료채취 작성'!$F39,'시료채취 작성'!E39,"") | D38: =IF($J$7='시료채취 작성'!$F39,'시료채취 작성'!G39,"") | E38: =IF($J$7='시료채취 작성'!$F39,'시료채취 작성'!H39,"") | F38: =IF($J$7='시료채취 작성'!$F39,'시료채취 작성'!I39,"") | G38: =IF($J$7='시료채취 작성'!$F39,'시료채취 작성'!J39,"") | H38: =IF($J$7='시료채취 작성'!$F39,'시료채취 작성'!K39,"") | I38: =IF($J$7='시료채취 작성'!$F39,'시료채취 작성'!L39,"") | J38: =IF($J$7='시료채취 작성'!$F39,'시료채취 작성'!M39,"") | K38: =IF($J$7='시료채취 작성'!$F39,'시료채취 작성'!N39,"") | M38: 4 | N38: =IF(B38="","",(WORKDAY($J$7,DAY(M38),0)))
A39: 총탄화수소 | B39: =IF($J$7='시료채취 작성'!F40,'시료채취 작성'!D40,"") | C39: =IF($J$7='시료채취 작성'!$F40,'시료채취 작성'!E40,"") | D39: =IF($J$7='시료채취 작성'!$F40,'시료채취 작성'!G40,"") | E39: =IF($J$7='시료채취 작성'!$F40,'시료채취 작성'!H40,"") | M39: 현장측정 | N39: =IF(B39="","",(WORKDAY($J$7,DAY(M39),0)))
A40: 벤조(a)피렌 | B40: =IF($J$7='시료채취 작성'!F41,'시료채취 작성'!D41,"") | C40: =IF($J$7='시료채취 작성'!$F41,'시료채취 작성'!E42,"") | D40: =IF($J$7='시료채취 작성'!$F41,'시료채취 작성'!G41,"") | E40: =IF($J$7='시료채취 작성'!$F41,'시료채취 작성'!H41,"") | F40: =IF($J$7='시료채취 작성'!$F41,'시료채취 작성'!I41,"") | G40: =IF($J$7='시료채취 작성'!$F41,'시료채취 작성'!J41,"") | H40: =IF($J$7='시료채취 작성'!$F41,'시료채취 작성'!K41,"") | M40: 9 | N40: =IF(B40="","",(WORKDAY($J$7,DAY(M40),0)))
A41: 염화비닐 | B41: =IF($J$7='시료채취 작성'!F42,'시료채취 작성'!D42,"") | C41: =IF($J$7='시료채취 작성'!$F42,'시료채취 작성'!#REF!,"") | D41: =IF($J$7='시료채취 작성'!$F42,'시료채취 작성'!G42,"") | E41: =IF($J$7='시료채취 작성'!$F42,'시료채취 작성'!H42,"") | F41: =IF($J$7='시료채취 작성'!$F42,'시료채취 작성'!I42,"") | G41: =IF($J$7='시료채취 작성'!$F42,'시료채취 작성'!J42,"") | H41: =IF($J$7='시료채취 작성'!$F42,'시료채취 작성'!K42,"") | M41: 9 | N41: =IF(B41="","",(WORKDAY($J$7,DAY(M41),0)))
A42: 벤젠 | B42: =IF($J$7='시료채취 작성'!F43,'시료채취 작성'!D43,"") | C42: =IF($J$7='시료채취 작성'!$F43,'시료채취 작성'!E43,"") | D42: =IF($J$7='시료채취 작성'!$F43,'시료채취 작성'!G43,"") | E42: =IF($J$7='시료채취 작성'!$F43,'시료채취 작성'!H43,"") | F42: =IF($J$7='시료채취 작성'!$F43,'시료채취 작성'!I43,"") | G42: =IF($J$7='시료채취 작성'!$F43,'시료채취 작성'!J43,"") | H42: =IF($J$7='시료채취 작성'!$F43,'시료채취 작성'!K43,"") | M42: 9 | N42: =IF(B42="","",(WORKDAY($J$7,DAY(M42),0)))
A43: 디클로로메탄 | B43: =IF($J$7='시료채취 작성'!F44,'시료채취 작성'!D44,"") | C43: =IF($J$7='시료채취 작성'!$F44,'시료채취 작성'!E44,"") | D43: =IF($J$7='시료채취 작성'!$F44,'시료채취 작성'!G44,"") | E43: =IF($J$7='시료채취 작성'!$F44,'시료채취 작성'!H44,"") | F43: =IF($J$7='시료채취 작성'!$F44,'시료채취 작성'!I44,"") | G43: =IF($J$7='시료채취 작성'!$F44,'시료채취 작성'!J44,"") | H43: =IF($J$7='시료채취 작성'!$F44,'시료채취 작성'!K44,"") | M43: 9 | N43: =IF(B43="","",(WORKDAY($J$7,DAY(M43),0)))
A44: 트리클로로에틸렌 | B44: =IF($J$7='시료채취 작성'!F45,'시료채취 작성'!D45,"") | C44: =IF($J$7='시료채취 작성'!$F45,'시료채취 작성'!E45,"") | D44: =IF($J$7='시료채취 작성'!$F45,'시료채취 작성'!G45,"") | E44: =IF($J$7='시료채취 작성'!$F45,'시료채취 작성'!H45,"") | F44: =IF($J$7='시료채취 작성'!$F45,'시료채취 작성'!I45,"") | G44: =IF($J$7='시료채취 작성'!$F45,'시료채취 작성'!J45,"") | H44: =IF($J$7='시료채취 작성'!$F45,'시료채취 작성'!K45,"") | M44: 9 | N44: =IF(B44="","",(WORKDAY($J$7,DAY(M44),0)))
A45: 1,3-부타디엔 | B45: =IF($J$7='시료채취 작성'!F46,'시료채취 작성'!D46,"") | C45: =IF($J$7='시료채취 작성'!$F46,'시료채취 작성'!E46,"") | D45: =IF($J$7='시료채취 작성'!$F46,'시료채취 작성'!G46,"") | E45: =IF($J$7='시료채취 작성'!$F46,'시료채취 작성'!H46,"") | F45: =IF($J$7='시료채취 작성'!$F46,'시료채취 작성'!I46,"") | G45: =IF($J$7='시료채취 작성'!$F46,'시료채취 작성'!J46,"") | H45: =IF($J$7='시료채취 작성'!$F46,'시료채취 작성'!K46,"") | M45: 9 | N45: =IF(B45="","",(WORKDAY($J$7,DAY(M45),0)))
...

Sheet 20261028
A2: 시료채취기록부 | J2: 기술책임자
A7: 사업장명 | B7: ='시료채취 작성'!C4 -> 지에스파워㈜ 부천열병합발전처 | C7: 업종 | D7: ='시료채취 작성'!F4 -> 화력발전업(35113) | G7: 굴뚝명 | H7: ='시료채취 작성'!M4 -> #A-30 | I7: 날짜 | J7: ='시료채취 작성'!C7 -> 46323
A8: 기상 | B8: 기온(℃) | C8: 습도(%) | E8: 기압(mmHg) | G8: 풍향 | I8: 풍속(m/s)
A9: =IF(J7='시료채취 작성'!C7,'시료채취 작성'!D7," ") -> 맑음 | B9: =IF(J7='시료채취 작성'!C7,'시료채취 작성'!E7," ") -> 28.9 | C9: =IF(J7='시료채취 작성'!C7,'시료채취 작성'!G7) -> 25 | E9: =IF(J7='시료채취 작성'!C7,'시료채취 작성'!I7," ") -> 778 | G9: =IF(J7='시료채취 작성'!C7,'시료채취 작성'!K7," ") -> 동 | I9: =IF(J7='시료채취 작성'!C7,'시료채취 작성'!M7," ") -> 2.5
A10: 물질명 | B10: 시료번호 | C10: sampler No. | D10: 측정일시 | F10: 채취유량 | I10: 샘플러 | M10: 시험검사기간 | N10: 분석기한
D11: 시작 | E11: 종료 | F11: 시작값 | G11: 종료값 | H11: 채취유량(L) | I11: 온도(℃) | J11: 압력(mmH2O) | K11: 압력(mmHg)
A12: 먼지 | B12: =IF($J$7='시료채취 작성'!F13,'시료채취 작성'!D13,"") | C12: =IF($J$7='시료채취 작성'!$F13,'시료채취 작성'!E13,"") | D12: =IF($J$7='시료채취 작성'!$F13,'시료채취 작성'!G13,"") | E12: =IF($J$7='시료채취 작성'!$F13,'시료채취 작성'!H13,"") | F12: =IF($J$7='시료채취 작성'!$F13,'시료채취 작성'!I13,"") | G12: =IF($J$7='시료채취 작성'!$F13,'시료채취 작성'!J13,"") | H12: =IF($J$7='시료채취 작성'!$F13,'시료채취 작성'!K13,"") | M12: 2 | N12: =IF(B12="","",(WORKDAY($J$7,DAY(M12),0)))
A13: 황산화물 | B13: =IF($J$7='시료채취 작성'!F14,'시료채취 작성'!D14,"") | C13: =IF($J$7='시료채취 작성'!$F14,'시료채취 작성'!E14,"") | D13: =IF($J$7='시료채취 작성'!$F14,'시료채취 작성'!G14,"") | E13: =IF($J$7='시료채취 작성'!$F14,'시료채취 작성'!H14,"") | M13: 현장측정 | N13: 현장측정
A14: 질소산화물 | B14: =IF($J$7='시료채취 작성'!F15,'시료채취 작성'!D15,"") | C14: =IF($J$7='시료채취 작성'!$F15,'시료채취 작성'!E15,"") | D14: =IF($J$7='시료채취 작성'!$F15,'시료채취 작성'!G15,"") | E14: =IF($J$7='시료채취 작성'!$F15,'시료채취 작성'!H15,"") | M14: 현장측정 | N14: 현장측정
A15: 일산화탄소 | C15: =IF($J$7='시료채취 작성'!$F16,'시료채취 작성'!E16,"") | D15: =IF($J$7='시료채취 작성'!$F16,'시료채취 작성'!G16,"") | E15: =IF($J$7='시료채취 작성'!$F16,'시료채취 작성'!H16,"") | M15: 현장측정 | N15: 현장측정
A16: 암모니아(BA) | B16: =IF($J$7='시료채취 작성'!F17,'시료채취 작성'!D17,"") -> 1028-GSP-#A-30-NH3-BA-1 | C16: =IF($J$7='시료채취 작성'!$F17,'시료채취 작성'!E17,"") -> 가스샘플러1 | D16: =IF($J$7='시료채취 작성'!$F17,'시료채취 작성'!G17,"") -> 0.47777778 | E16: =IF($J$7='시료채취 작성'!$F17,'시료채취 작성'!H17,"") -> 0.48680556 | F16: =IF($J$7='시료채취 작성'!$F17,'시료채취 작성'!I17,"") -> 2109.15 | G16: =IF($J$7='시료채취 작성'!$F17,'시료채취 작성'!J17,"") -> 2129.5 | H16: =IF($J$7='시료채취 작성'!$F17,'시료채취 작성'!K17,"") -> 20.058995 | I16: =IF($J$7='시료채취 작성'!$F17,'시료채취 작성'!L17,"") -> 25 | J16: =IF($J$7='시료채취 작성'!$F17,'시료채취 작성'!M17,"") -> 20 | K16: =IF($J$7='시료채취 작성'!$F17,'시료채취 작성'!N17,"") -> 1.4705882 | M16: 3 | N16: =IF(B16="","",(WORKDAY($J$7,DAY(M16),0))) -> 46328
A17: 암모니아(HP) | B17: =IF($J$7='시료채취 작성'!F18,'시료채취 작성'!D18,"") -> 1028-GSP-#A-30-NH3-H2O2-1 | C17: =IF($J$7='시료채취 작성'!$F18,'시료채취 작성'!E18,"") -> 가스샘플러1 | D17: =IF($J$7='시료채취 작성'!$F18,'시료채취 작성'!G18,"") -> 0.4875 | E17: =IF($J$7='시료채취 작성'!$F18,'시료채취 작성'!H18,"") -> 0.49583333 | F17: =IF($J$7='시료채취 작성'!$F18,'시료채취 작성'!I18,"") -> 2129.5 | G17: =IF($J$7='시료채취 작성'!$F18,'시료채취 작성'!J18,"") -> 2150.1 | H17: =IF($J$7='시료채취 작성'!$F18,'시료채취 작성'!K18,"") -> 20.30542 | I17: =IF($J$7='시료채취 작성'!$F18,'시료채취 작성'!L18,"") -> 25 | J17: =IF($J$7='시료채취 작성'!$F18,'시료채취 작성'!M18,"") -> 20 | K17: =IF($J$7='시료채취 작성'!$F18,'시료채취 작성'!N18,"") -> 1.4705882 | M17: 3 | N17: =IF(B17="","",(WORKDAY($J$7,DAY(M17),0))) -> 46328
A18: 불소 | B18: =IF($J$7='시료채취 작성'!F19,'시료채취 작성'!D19,"") | C18: =IF($J$7='시료채취 작성'!$F19,'시료채취 작성'!E19,"") | D18: =IF($J$7='시료채취 작성'!$F19,'시료채취 작성'!G19,"") | E18: =IF($J$7='시료채취 작성'!$F19,'시료채취 작성'!H19,"") | F18: =IF($J$7='시료채취 작성'!$F19,'시료채취 작성'!I19,"") | G18: =IF($J$7='시료채취 작성'!$F19,'시료채취 작성'!J19,"") | H18: =IF($J$7='시료채취 작성'!$F19,'시료채취 작성'!K19,"") | I18: =IF($J$7='시료채취 작성'!$F19,'시료채취 작성'!L19,"") | J18: =IF($J$7='시료채취 작성'!$F19,'시료채취 작성'!M19,"") | K18: =IF($J$7='시료채취 작성'!$F19,'시료채취 작성'!N19,"") | M18: 4 | N18: =IF(B18="","",(WORKDAY($J$7,DAY(M18),0)))
A19: 염화수소 | B19: =IF($J$7='시료채취 작성'!F20,'시료채취 작성'!D20,"") | C19: =IF($J$7='시료채취 작성'!$F20,'시료채취 작성'!E20,"") | D19: =IF($J$7='시료채취 작성'!$F20,'시료채취 작성'!G20,"") | E19: =IF($J$7='시료채취 작성'!$F20,'시료채취 작성'!H20,"") | F19: =IF($J$7='시료채취 작성'!$F20,'시료채취 작성'!I20,"") | G19: =IF($J$7='시료채취 작성'!$F20,'시료채취 작성'!J20,"") | H19: =IF($J$7='시료채취 작성'!$F20,'시료채취 작성'!K20,"") | I19: =IF($J$7='시료채취 작성'!$F20,'시료채취 작성'!L20,"") | J19: =IF($J$7='시료채취 작성'!$F20,'시료채취 작성'!M20,"") | K19: =IF($J$7='시료채취 작성'!$F20,'시료채취 작성'!N20,"") | M19: 3 | N19: =IF(B19="","",(WORKDAY($J$7,DAY(M19),0)))
A20: 황화수소 | B20: =IF($J$7='시료채취 작성'!F21,'시료채취 작성'!D21,"") | C20: =IF($J$7='시료채취 작성'!$F21,'시료채취 작성'!E21,"") | D20: =IF($J$7='시료채취 작성'!$F21,'시료채취 작성'!G21,"") | E20: =IF($J$7='시료채취 작성'!$F21,'시료채취 작성'!H21,"") | F20: =IF($J$7='시료채취 작성'!$F21,'시료채취 작성'!I21,"") | G20: =IF($J$7='시료채취 작성'!$F21,'시료채취 작성'!J21,"") | H20: =IF($J$7='시료채취 작성'!$F21,'시료채취 작성'!K21,"") | I20: =IF($J$7='시료채취 작성'!$F21,'시료채취 작성'!L21,"") | J20: =IF($J$7='시료채취 작성'!$F21,'시료채취 작성'!M21,"") | K20: =IF($J$7='시료채취 작성'!$F21,'시료채취 작성'!N21,"") | M20: 4 | N20: =IF(B20="","",(WORKDAY($J$7,DAY(M20),0)))
A21: 시안화수소 | B21: =IF($J$7='시료채취 작성'!F22,'시료채취 작성'!D22,"") | C21: =IF($J$7='시료채취 작성'!$F22,'시료채취 작성'!E22,"") | D21: =IF($J$7='시료채취 작성'!$F22,'시료채취 작성'!G22,"") | E21: =IF($J$7='시료채취 작성'!$F22,'시료채취 작성'!H22,"") | F21: =IF($J$7='시료채취 작성'!$F22,'시료채취 작성'!I22,"") | G21: =IF($J$7='시료채취 작성'!$F22,'시료채취 작성'!J22,"") | H21: =IF($J$7='시료채취 작성'!$F22,'시료채취 작성'!K22,"") | I21: =IF($J$7='시료채취 작성'!$F22,'시료채취 작성'!L22,"") | J21: =IF($J$7='시료채취 작성'!$F22,'시료채취 작성'!M22,"") | K21: =IF($J$7='시료채취 작성'!$F22,'시료채취 작성'!N22,"") | M21: 3 | N21: =IF(B21="","",(WORKDAY($J$7,DAY(M21),0)))
A22: 하이드라진 | B22: =IF($J$7='시료채취 작성'!F23,'시료채취 작성'!D23,"") | C22: =IF($J$7='시료채취 작성'!$F23,'시료채취 작성'!E23,"") | D22: =IF($J$7='시료채취 작성'!$F23,'시료채취 작성'!G23,"") | E22: =IF($J$7='시료채취 작성'!$F23,'시료채취 작성'!H23,"") | F22: =IF($J$7='시료채취 작성'!$F23,'시료채취 작성'!I23,"") | G22: =IF($J$7='시료채취 작성'!$F23,'시료채취 작성'!J23,"") | H22: =IF($J$7='시료채취 작성'!$F23,'시료채취 작성'!K23,"") | I22: =IF($J$7='시료채취 작성'!$F23,'시료채취 작성'!L23,"") | J22: =IF($J$7='시료채취 작성'!$F23,'시료채취 작성'!M23,"") | K22: =IF($J$7='시료채취 작성'!$F23,'시료채취 작성'!N23,"")
A23: 이황화탄소 | B23: =IF($J$7='시료채취 작성'!F24,'시료채취 작성'!D24,"") | C23: =IF($J$7='시료채취 작성'!$F24,'시료채취 작성'!E24,"") | D23: =IF($J$7='시료채취 작성'!$F24,'시료채취 작성'!G24,"") | E23: =IF($J$7='시료채취 작성'!$F24,'시료채취 작성'!H24,"") | F23: =IF($J$7='시료채취 작성'!$F24,'시료채취 작성'!I24,"") | G23: =IF($J$7='시료채취 작성'!$F24,'시료채취 작성'!J24,"") | H23: =IF($J$7='시료채취 작성'!$F24,'시료채취 작성'!K24,"") | M23: 9 | N23: =IF(B23="","",(WORKDAY($J$7,DAY(M23),0)))
A24: 구리 | B24: =IF($J$7='시료채취 작성'!F25,'시료채취 작성'!D25,"") | C24: =IF($J$7='시료채취 작성'!$F25,'시료채취 작성'!E25,"") | D24: =IF($J$7='시료채취 작성'!$F25,'시료채취 작성'!G25,"") | E24: =IF($J$7='시료채취 작성'!$F25,'시료채취 작성'!H25,"") | F24: =IF($J$7='시료채취 작성'!$F25,'시료채취 작성'!I25,"") | G24: =IF($J$7='시료채취 작성'!$F25,'시료채취 작성'!J25,"") | H24: =IF($J$7='시료채취 작성'!$F25,'시료채취 작성'!K25,"") | M24: 6 | N24: =IF(B24="","",(WORKDAY($J$7,DAY(M24),0)))
A25: 카드륨 | B25: =IF($J$7='시료채취 작성'!F26,'시료채취 작성'!D26,"") -> 1028-GSP-#A-30-M-1 | C25: =IF($J$7='시료채취 작성'!$F26,'시료채취 작성'!E26,"") -> 입자샘플러4 | D25: =IF($J$7='시료채취 작성'!$F26,'시료채취 작성'!G26,"") -> 0.47777778 | E25: =IF($J$7='시료채취 작성'!$F26,'시료채취 작성'!H26,"") -> 0.53333333 | F25: =IF($J$7='시료채취 작성'!$F26,'시료채취 작성'!I26,"") -> 6783.07 | G25: =IF($J$7='시료채취 작성'!$F26,'시료채취 작성'!J26,"") -> 7951.86 | H25: =IF($J$7='시료채취 작성'!$F26,'시료채취 작성'!K26,"") -> 1165.9849 | M25: 6 | N25: =IF(B25="","",(WORKDAY($J$7,DAY(M25),0))) -> 46331
A26: 납 | B26: =IF($J$7='시료채취 작성'!F27,'시료채취 작성'!D27,"") -> 1028-GSP-#A-30-M-1 | C26: =IF($J$7='시료채취 작성'!$F27,'시료채취 작성'!E27,"") -> 입자샘플러4 | D26: =IF($J$7='시료채취 작성'!$F27,'시료채취 작성'!G27,"") -> 0.47777778 | E26: =IF($J$7='시료채취 작성'!$F27,'시료채취 작성'!H27,"") -> 0.53333333 | F26: =IF($J$7='시료채취 작성'!$F27,'시료채취 작성'!I27,"") -> 6783.07 | G26: =IF($J$7='시료채취 작성'!$F27,'시료채취 작성'!J27,"") -> 7951.86 | H26: =IF($J$7='시료채취 작성'!$F27,'시료채취 작성'!K27,"") -> 1165.9849 | M26: 6 | N26: =IF(B26="","",(WORKDAY($J$7,DAY(M26),0))) -> 46331
A27: 크롬 | B27: =IF($J$7='시료채취 작성'!F28,'시료채취 작성'!D28,"") -> 1028-GSP-#A-30-M-1 | C27: =IF($J$7='시료채취 작성'!$F28,'시료채취 작성'!E28,"") -> 입자샘플러4 | D27: =IF($J$7='시료채취 작성'!$F28,'시료채취 작성'!G28,"") -> 0.47777778 | E27: =IF($J$7='시료채취 작성'!$F28,'시료채취 작성'!H28,"") -> 0.53333333 | F27: =IF($J$7='시료채취 작성'!$F28,'시료채취 작성'!I28,"") -> 6783.07 | G27: =IF($J$7='시료채취 작성'!$F28,'시료채취 작성'!J28,"") -> 7951.86 | H27: =IF($J$7='시료채취 작성'!$F28,'시료채취 작성'!K28,"") -> 1165.9849 | M27: 6 | N27: =IF(B27="","",(WORKDAY($J$7,DAY(M27),0))) -> 46331
A28: 니켈 | B28: =IF($J$7='시료채취 작성'!F29,'시료채취 작성'!D29,"") -> 1028-GSP-#A-30-M-1 | C28: =IF($J$7='시료채취 작성'!$F29,'시료채취 작성'!E29,"") -> 입자샘플러4 | D28: =IF($J$7='시료채취 작성'!$F29,'시료채취 작성'!G29,"") -> 0.47777778 | E28: =IF($J$7='시료채취 작성'!$F29,'시료채취 작성'!H29,"") -> 0.53333333 | F28: =IF($J$7='시료채취 작성'!$F29,'시료채취 작성'!I29,"") -> 6783.07 | G28: =IF($J$7='시료채취 작성'!$F29,'시료채취 작성'!J29,"") -> 7951.86 | H28: =IF($J$7='시료채취 작성'!$F29,'시료채취 작성'!K29,"") -> 1165.9849 | M28: 6 | N28: =IF(B28="","",(WORKDAY($J$7,DAY(M28),0))) -> 46331
A29: 아연 | B29: =IF($J$7='시료채취 작성'!F30,'시료채취 작성'!D30,"") | C29: =IF($J$7='시료채취 작성'!$F30,'시료채취 작성'!E30,"") | D29: =IF($J$7='시료채취 작성'!$F30,'시료채취 작성'!G30,"") | E29: =IF($J$7='시료채취 작성'!$F30,'시료채취 작성'!H30,"") | F29: =IF($J$7='시료채취 작성'!$F30,'시료채취 작성'!I30,"") | G29: =IF($J$7='시료채취 작성'!$F30,'시료채취 작성'!J30,"") | H29: =IF($J$7='시료채취 작성'!$F30,'시료채취 작성'!K30,"") | M29: 6 | N29: =IF(B29="","",(WORKDAY($J$7,DAY(M29),0)))
A30: 베릴륨 | B30: =IF($J$7='시료채취 작성'!F31,'시료채취 작성'!D31,"") | C30: =IF($J$7='시료채취 작성'!$F31,'시료채취 작성'!E31,"") | D30: =IF($J$7='시료채취 작성'!$F31,'시료채취 작성'!G31,"") | E30: =IF($J$7='시료채취 작성'!$F31,'시료채취 작성'!H31,"") | F30: =IF($J$7='시료채취 작성'!$F31,'시료채취 작성'!I31,"") | G30: =IF($J$7='시료채취 작성'!$F31,'시료채취 작성'!J31,"") | H30: =IF($J$7='시료채취 작성'!$F31,'시료채취 작성'!K31,"")
A31: 비소(입자상) | B31: =IF($J$7='시료채취 작성'!F32,'시료채취 작성'!D32,"") -> 1028-GSP-#A-30-M-1 | C31: =IF($J$7='시료채취 작성'!$F32,'시료채취 작성'!E32,"") -> 입자샘플러4 | D31: =IF($J$7='시료채취 작성'!$F32,'시료채취 작성'!G32,"") -> 0.47777778 | E31: =IF($J$7='시료채취 작성'!$F32,'시료채취 작성'!H32,"") -> 0.53333333 | F31: =IF($J$7='시료채취 작성'!$F32,'시료채취 작성'!I32,"") -> 6783.07 | G31: =IF($J$7='시료채취 작성'!$F32,'시료채취 작성'!J32,"") -> 7951.86 | H31: =IF($J$7='시료채취 작성'!$F32,'시료채취 작성'!K32,"") -> 1165.9849 | M31: 9 | N31: =IF(B31="","",(WORKDAY($J$7,DAY(M31),0))) -> 46336
A32: 비소(가스상) | B32: =IF($J$7='시료채취 작성'!F33,'시료채취 작성'!D33,"") -> 1028-GSP-#A-30-As-G-1 | C32: =IF($J$7='시료채취 작성'!$F33,'시료채취 작성'!E33,"") -> 입자샘플러4 | D32: =IF($J$7='시료채취 작성'!$F33,'시료채취 작성'!G33,"") -> 0.47777778 | E32: =IF($J$7='시료채취 작성'!$F33,'시료채취 작성'!H33,"") -> 0.53333333 | F32: =IF($J$7='시료채취 작성'!$F33,'시료채취 작성'!I33,"") -> 6783.07 | G32: =IF($J$7='시료채취 작성'!$F33,'시료채취 작성'!J33,"") -> 7951.86 | H32: =IF($J$7='시료채취 작성'!$F33,'시료채취 작성'!K33,"") -> 1165.9849 | M32: 9 | N32: =IF(B32="","",(WORKDAY($J$7,DAY(M32),0))) -> 46336
A33: 수은(입자상) 수은(가스상) | B33: =IF($J$7='시료채취 작성'!F34,'시료채취 작성'!D34,"") | C33: =IF($J$7='시료채취 작성'!$F34,'시료채취 작성'!E34,"") | D33: =IF($J$7='시료채취 작성'!$F34,'시료채취 작성'!G34,"") | E33: =IF($J$7='시료채취 작성'!$F34,'시료채취 작성'!H34,"") | F33: =IF($J$7='시료채취 작성'!$F34,'시료채취 작성'!I34,"") | G33: =IF($J$7='시료채취 작성'!$F34,'시료채취 작성'!J34,"") | H33: =IF($J$7='시료채취 작성'!$F34,'시료채취 작성'!K34,"") | M33: 9 | N33: =IF(B33="","",(WORKDAY($J$7,DAY(M33),0)))
A34: 알데하이드-1 | B34: =IF($J$7='시료채취 작성'!F35,'시료채취 작성'!D35,"") | C34: =IF($J$7='시료채취 작성'!$F35,'시료채취 작성'!E35,"") | D34: =IF($J$7='시료채취 작성'!$F35,'시료채취 작성'!G35,"") | E34: =IF($J$7='시료채취 작성'!$F35,'시료채취 작성'!H35,"") | F34: =IF($J$7='시료채취 작성'!$F35,'시료채취 작성'!I35,"") | G34: =IF($J$7='시료채취 작성'!$F35,'시료채취 작성'!J35,"") | H34: =IF($J$7='시료채취 작성'!$F35,'시료채취 작성'!K35,"") | I34: =IF($J$7='시료채취 작성'!$F35,'시료채취 작성'!L35,"") | J34: =IF($J$7='시료채취 작성'!$F35,'시료채취 작성'!M35,"") | K34: =IF($J$7='시료채취 작성'!$F35,'시료채취 작성'!N35,"") | M34: 7 | N34: =IF(B34="","",(WORKDAY($J$7,DAY(M34),0)))
A35: 알데하이드-2 | B35: =IF($J$7='시료채취 작성'!F36,'시료채취 작성'!D36,"") | C35: =IF($J$7='시료채취 작성'!$F36,'시료채취 작성'!E36,"") | D35: =IF($J$7='시료채취 작성'!$F36,'시료채취 작성'!G36,"") | E35: =IF($J$7='시료채취 작성'!$F36,'시료채취 작성'!H36,"") | F35: =IF($J$7='시료채취 작성'!$F36,'시료채취 작성'!I36,"") | G35: =IF($J$7='시료채취 작성'!$F36,'시료채취 작성'!J36,"") | H35: =IF($J$7='시료채취 작성'!$F36,'시료채취 작성'!K36,"") | I35: =IF($J$7='시료채취 작성'!$F36,'시료채취 작성'!L36,"") | J35: =IF($J$7='시료채취 작성'!$F36,'시료채취 작성'!M36,"") | K35: =IF($J$7='시료채취 작성'!$F36,'시료채취 작성'!N36,"") | N35: =IF(B35="","",(WORKDAY($J$7,DAY(M35),0)))
A36: 알데하이드-3 | B36: =IF($J$7='시료채취 작성'!F37,'시료채취 작성'!D37,"") | C36: =IF($J$7='시료채취 작성'!$F37,'시료채취 작성'!E37,"") | D36: =IF($J$7='시료채취 작성'!$F37,'시료채취 작성'!G37,"") | E36: =IF($J$7='시료채취 작성'!$F37,'시료채취 작성'!H37,"") | F36: =IF($J$7='시료채취 작성'!$F37,'시료채취 작성'!I37,"") | G36: =IF($J$7='시료채취 작성'!$F37,'시료채취 작성'!J37,"") | H36: =IF($J$7='시료채취 작성'!$F37,'시료채취 작성'!K37,"") | I36: =IF($J$7='시료채취 작성'!$F37,'시료채취 작성'!L37,"") | J36: =IF($J$7='시료채취 작성'!$F37,'시료채취 작성'!M37,"") | K36: =IF($J$7='시료채취 작성'!$F37,'시료채취 작성'!N37,"") | N36: =IF(B36="","",(WORKDAY($J$7,DAY(M36),0)))
A37: 페놀 | B37: =IF($J$7='시료채취 작성'!F38,'시료채취 작성'!D38,"") | C37: =IF($J$7='시료채취 작성'!$F38,'시료채취 작성'!E38,"") | D37: =IF($J$7='시료채취 작성'!$F38,'시료채취 작성'!G38,"") | E37: =IF($J$7='시료채취 작성'!$F38,'시료채취 작성'!H38,"") | F37: =IF($J$7='시료채취 작성'!$F38,'시료채취 작성'!I38,"") | G37: =IF($J$7='시료채취 작성'!$F38,'시료채취 작성'!J38,"") | H37: =IF($J$7='시료채취 작성'!$F38,'시료채취 작성'!K38,"") | I37: =IF($J$7='시료채취 작성'!$F38,'시료채취 작성'!L38,"") | J37: =IF($J$7='시료채취 작성'!$F38,'시료채취 작성'!M38,"") | K37: =IF($J$7='시료채취 작성'!$F38,'시료채취 작성'!N38,"") | M37: 4 | N37: =IF(B37="","",(WORKDAY($J$7,DAY(M37),0)))
A38: 브롬 | B38: =IF($J$7='시료채취 작성'!F39,'시료채취 작성'!D39,"") | C38: =IF($J$7='시료채취 작성'!$F39,'시료채취 작성'!E39,"") | D38: =IF($J$7='시료채취 작성'!$F39,'시료채취 작성'!G39,"") | E38: =IF($J$7='시료채취 작성'!$F39,'시료채취 작성'!H39,"") | F38: =IF($J$7='시료채취 작성'!$F39,'시료채취 작성'!I39,"") | G38: =IF($J$7='시료채취 작성'!$F39,'시료채취 작성'!J39,"") | H38: =IF($J$7='시료채취 작성'!$F39,'시료채취 작성'!K39,"") | I38: =IF($J$7='시료채취 작성'!$F39,'시료채취 작성'!L39,"") | J38: =IF($J$7='시료채취 작성'!$F39,'시료채취 작성'!M39,"") | K38: =IF($J$7='시료채취 작성'!$F39,'시료채취 작성'!N39,"") | M38: 4 | N38: =IF(B38="","",(WORKDAY($J$7,DAY(M38),0)))
A39: 총탄화수소 | B39: =IF($J$7='시료채취 작성'!F40,'시료채취 작성'!D40,"") | C39: =IF($J$7='시료채취 작성'!$F40,'시료채취 작성'!E40,"") | D39: =IF($J$7='시료채취 작성'!$F40,'시료채취 작성'!G40,"") | E39: =IF($J$7='시료채취 작성'!$F40,'시료채취 작성'!H40,"") | M39: 현장측정 | N39: =IF(B39="","",(WORKDAY($J$7,DAY(M39),0)))
A40: 벤조(a)피렌 | B40: =IF($J$7='시료채취 작성'!F41,'시료채취 작성'!D41,"") | C40: =IF($J$7='시료채취 작성'!$F41,'시료채취 작성'!E42,"") | D40: =IF($J$7='시료채취 작성'!$F41,'시료채취 작성'!G41,"") | E40: =IF($J$7='시료채취 작성'!$F41,'시료채취 작성'!H41,"") | F40: =IF($J$7='시료채취 작성'!$F41,'시료채취 작성'!I41,"") | G40: =IF($J$7='시료채취 작성'!$F41,'시료채취 작성'!J41,"") | H40: =IF($J$7='시료채취 작성'!$F41,'시료채취 작성'!K41,"") | M40: 9 | N40: =IF(B40="","",(WORKDAY($J$7,DAY(M40),0)))
A41: 염화비닐 | B41: =IF($J$7='시료채취 작성'!F42,'시료채취 작성'!D42,"") | C41: =IF($J$7='시료채취 작성'!$F42,'시료채취 작성'!#REF!,"") | D41: =IF($J$7='시료채취 작성'!$F42,'시료채취 작성'!G42,"") | E41: =IF($J$7='시료채취 작성'!$F42,'시료채취 작성'!H42,"") | F41: =IF($J$7='시료채취 작성'!$F42,'시료채취 작성'!I42,"") | G41: =IF($J$7='시료채취 작성'!$F42,'시료채취 작성'!J42,"") | H41: =IF($J$7='시료채취 작성'!$F42,'시료채취 작성'!K42,"") | M41: 9 | N41: =IF(B41="","",(WORKDAY($J$7,DAY(M41),0)))
A42: 벤젠 | B42: =IF($J$7='시료채취 작성'!F43,'시료채취 작성'!D43,"") -> 1028-GSP-#A-30-VOCs-1~3 | C42: =IF($J$7='시료채취 작성'!$F43,'시료채취 작성'!E43,"") -> 음압상자1 | D42: =IF($J$7='시료채취 작성'!$F43,'시료채취 작성'!G43,"") -> 0.47916667 | E42: =IF($J$7='시료채취 작성'!$F43,'시료채취 작성'!H43,"") -> 0.49652778 | F42: =IF($J$7='시료채취 작성'!$F43,'시료채취 작성'!I43,"") -> 0 | G42: =IF($J$7='시료채취 작성'!$F43,'시료채취 작성'!J43,"") -> 9 | H42: =IF($J$7='시료채취 작성'!$F43,'시료채취 작성'!K43,"") -> 9 | M42: 9 | N42: =IF(B42="","",(WORKDAY($J$7,DAY(M42),0))) -> 46336
A43: 디클로로메탄 | B43: =IF($J$7='시료채취 작성'!F44,'시료채취 작성'!D44,"") | C43: =IF($J$7='시료채취 작성'!$F44,'시료채취 작성'!E44,"") | D43: =IF($J$7='시료채취 작성'!$F44,'시료채취 작성'!G44,"") | E43: =IF($J$7='시료채취 작성'!$F44,'시료채취 작성'!H44,"") | F43: =IF($J$7='시료채취 작성'!$F44,'시료채취 작성'!I44,"") | G43: =IF($J$7='시료채취 작성'!$F44,'시료채취 작성'!J44,"") | H43: =IF($J$7='시료채취 작성'!$F44,'시료채취 작성'!K44,"") | M43: 9 | N43: =IF(B43="","",(WORKDAY($J$7,DAY(M43),0)))
A44: 트리클로로에틸렌 | B44: =IF($J$7='시료채취 작성'!F45,'시료채취 작성'!D45,"") | C44: =IF($J$7='시료채취 작성'!$F45,'시료채취 작성'!E45,"") | D44: =IF($J$7='시료채취 작성'!$F45,'시료채취 작성'!G45,"") | E44: =IF($J$7='시료채취 작성'!$F45,'시료채취 작성'!H45,"") | F44: =IF($J$7='시료채취 작성'!$F45,'시료채취 작성'!I45,"") | G44: =IF($J$7='시료채취 작성'!$F45,'시료채취 작성'!J45,"") | H44: =IF($J$7='시료채취 작성'!$F45,'시료채취 작성'!K45,"") | M44: 9 | N44: =IF(B44="","",(WORKDAY($J$7,DAY(M44),0)))
A45: 1,3-부타디엔 | B45: =IF($J$7='시료채취 작성'!F46,'시료채취 작성'!D46,"") | C45: =IF($J$7='시료채취 작성'!$F46,'시료채취 작성'!E46,"") | D45: =IF($J$7='시료채취 작성'!$F46,'시료채취 작성'!G46,"") | E45: =IF($J$7='시료채취 작성'!$F46,'시료채취 작성'!H46,"") | F45: =IF($J$7='시료채취 작성'!$F46,'시료채취 작성'!I46,"") | G45: =IF($J$7='시료채취 작성'!$F46,'시료채취 작성'!J46,"") | H45: =IF($J$7='시료채취 작성'!$F46,'시료채취 작성'!K46,"") | M45: 9 | N45: =IF(B45="","",(WORKDAY($J$7,DAY(M45),0)))
...
